Workbook

Sheet Contracted Suppliers_Live
B1: Contracted Supplier Tracking Sheet
B3: COLOMBIA - VENEZUELA
A4: Vendor account | B4: Supplier name | C4: Type of contract | D4: Contract Start Date | E4: Contract End Date | F4: Notice date (days) | G4: ATC status | H4: ATC clearance expiration date | I4: Site | J4: ATC | K4: Contract Reference | L4: Category of Goods or Services | M4: Contact Person | N4: Contact Phone/Fax Numbers | O4: Contact Email Address | P4: Ownership or Leadership Information | Q4: Name of Financial Institution (for bank-to-bank transactations only) | R4: Name of Account Holder (for bank-to-bank transactations only) | S4: Notes | T4: Valor Gastado COP | U4: Valor Gastado USD | V4: Vendor anticipated spend USD | W4: Number of Amendments | X4: Valor gastado USD | Z4: ATC | AA4: Notification to SC | AB4: Notification to Supplier | AC4: Amendments
A5: 10000514 | B5: =VLOOKUP(A5,'All vendors'!A:Z,2,0) -> Atlantic Tactical Group SAS | C5: MPA | D5: 44860 | E5: 45707 | F5: 30 | G5: =VLOOKUP(A5,'All vendors'!B:E,4,0) -> #N/A | H5: =VLOOKUP(A5,'All vendors'!B:E,3,0) -> #N/A | I5: COL-Bogotá | J5: =VLOOKUP(A5,'All vendors'!A:Z,13,0) -> 45654.504 | K5: MPA/2022/022 | L5: Supply of goods | M5: =VLOOKUP(A5,'All vendors'!A:Z,11,0) -> Juan Diego Chaparro Bayona | N5: =VLOOKUP(A5,'All vendors'!A:Z,12,0) -> +573158829720 | O5: =VLOOKUP(A5,'All vendors'!A:Z,15,0) -> ventas1@rescateydefensa.com | P5: Erika Viviana Zambrano | Q5: Banco de Bogotá | R5: Asia Trading Group SAS | S5: Sin Observaciones. Se renovara | T5: 0 | U5: =T5/4000 -> 0 | V5: =VLOOKUP(A5,'All vendors'!A:Z,17,0) -> 999999999 | W5: 0 | Z5: =IF(H5>E5,"No actions","Update ATC") -> #N/A | AA5: =IF(E5<(TODAY()+90),"Send email to SC","No actions") -> Send email to SC | AB5: =IF(E5<=(TODAY()+F5),"Send notification to supplier","No actions") -> Send notification to supplier | AC5: =IF((E5-D5)>720,W5>0, "No actions") -> FALSE | AD5: 999999999 | AE5: 45590
A6: 10000519 | B6: =VLOOKUP(A6,'All vendors'!A:Z,2,0) -> Comercializadora Y Distribuidora Raygo S.A.S | C6: MPA | D6: 44860 | E6: 45590 | F6: 30 | G6: =VLOOKUP(A6,'All vendors'!B:E,4,0) -> #N/A | H6: =VLOOKUP(A6,'All vendors'!B:E,3,0) -> #N/A | I6: COL-Bogotá | J6: =VLOOKUP(A6,'All vendors'!A:Z,13,0) -> 45658.695 | K6: MPA/2020/024 | L6: Supply of goods | M6: =VLOOKUP(A6,'All vendors'!A:Z,11,0) -> Patricia Gonzalez Velasquez | N6: =VLOOKUP(A6,'All vendors'!A:Z,12,0) -> +573005821543 | O6: =VLOOKUP(A6,'All vendors'!A:Z,15,0) -> comercializadoraraygosas@hotmai.com | P6: Patricia Gonzalez | Q6: Davivienda | R6: COMERCIALIZADORA Y DISTRIBUIDORA RAYGO SAS | S6: Sin Observaciones. No se Renovara | T6: 0 | U6: =T6/4000 -> 0 | V6: =VLOOKUP(A6,'All vendors'!A:Z,17,0) -> 999999999 | W6: 0 | Z6: =IF(H6>E6,"No actions","Update ATC") -> #N/A | AA6: =IF(E6<(TODAY()+90),"Send email to SC","No actions") -> Send email to SC | AB6: =IF(E6<=(TODAY()+F6),"Send notification to supplier","No actions") -> Send notification to supplier | AC6: =IF((E6-D6)>720,W6>0, "No actions") -> FALSE | AD6: 999999999 | AE6: 45590
A7: 10019523 | B7: =VLOOKUP(A7,'All vendors'!A:Z,2,0) -> Suarez Silva & Asociados | C7: Serv Agreem | D7: 45231 | E7: 45595 | F7: 30 | G7: =VLOOKUP(A7,'All vendors'!B:E,4,0) -> #N/A | H7: =VLOOKUP(A7,'All vendors'!B:E,3,0) -> #N/A | I7: VEN-Caracas | J7: =VLOOKUP(A7,'All vendors'!A:Z,13,0) -> 45609.292 | K7: SC+2500/2022/057 | L7: Legal Services | M7: =VLOOKUP(A7,'All vendors'!A:Z,11,0) -> Alejandra Suarez Silva | N7: =VLOOKUP(A7,'All vendors'!A:Z,12,0) -> +584144662227 | O7: =VLOOKUP(A7,'All vendors'!A:Z,15,0) -> Suarezsilvaasociados@gmail.com | P7: Claudia Patricia Flórez | Q7: Davivienda | R7: Movlife SAS | S7: En proceso de renovación | T7: 0 | U7: =T7/4000 -> 0 | V7: =VLOOKUP(A7,'All vendors'!A:Z,17,0) -> 999999999 | W7: 0 | AD7: 999999999 | AE7: 45595
A8: 10001556 | B8: =VLOOKUP(A8,'All vendors'!A:Z,2,0) -> Soluciones Empresariales Horizonte S.A.S. B.I.C. | C8: MSA | D8: 44834 | E8: 45597 | F8: 30 | G8: =VLOOKUP(A8,'All vendors'!B:E,4,0) -> #N/A | H8: =VLOOKUP(A8,'All vendors'!B:E,3,0) -> #N/A | I8: COL-Bogotá | J8: =VLOOKUP(A8,'All vendors'!A:Z,13,0) -> 45762.049 | K8: MSA/2022/036 | L8: Accounting services | M8: =VLOOKUP(A8,'All vendors'!A:Z,11,0) -> Miguel Garavito | N8: =VLOOKUP(A8,'All vendors'!A:Z,12,0) -> +573209040453 | O8: =VLOOKUP(A8,'All vendors'!A:Z,15,0) -> nomina1bogota@gsh.com.co | R8: Darlyng Xiomara Aceros | S8: Sin Observaciones | T8: 0 | U8: =T8/4000 -> 0 | V8: =VLOOKUP(A8,'All vendors'!A:Z,17,0) -> 999999999 | W8: 0 | Z8: =IF(H8>E8,"No actions","Update ATC") -> #N/A | AA8: =IF(E8<(TODAY()+90),"Send email to SC","No actions") -> Send email to SC | AB8: =IF(E8<=(TODAY()+F8),"Send notification to supplier","No actions") -> Send notification to supplier | AC8: =IF((E8-D8)>720,W8>0, "No actions") -> FALSE | AD8: 999999999 | AE8: 45597
A9: 10000341 | B9: =VLOOKUP(A9,'All vendors'!A:Z,2,0) -> Del Mar Abogados SAS | C9: MSA | D9: 43612 | E9: 45597 | F9: 30 | G9: =VLOOKUP(A9,'All vendors'!B:E,4,0) -> #N/A | H9: =VLOOKUP(A9,'All vendors'!B:E,3,0) -> #N/A | I9: COL-Bogotá | J9: =VLOOKUP(A9,'All vendors'!A:Z,13,0) -> 45846.268 | K9: SERV/PF/BOG/005-19 | L9: Legal Services | M9: =VLOOKUP(A9,'All vendors'!A:Z,11,0) -> Caroline Del Mar Gallardo Rojas | N9: =VLOOKUP(A9,'All vendors'!A:Z,12,0) -> +5713221386 | O9: =VLOOKUP(A9,'All vendors'!A:Z,15,0) -> caroline@grupodelmar.com | P9: Julio Gallardo Rojas | Q9: Davivienda | R9: DEL MAR ABOGADOS ASOCIADOS LTDA | S9: Sin Observaciones | T9: 0 | U9: =T9/4000 -> 0 | V9: =VLOOKUP(A9,'All vendors'!A:Z,17,0) -> 999999999 | W9: 0 | Z9: =IF(H9>E9,"No actions","Update ATC") -> #N/A | AA9: =IF(E9<(TODAY()+90),"Send email to SC","No actions") -> Send email to SC | AB9: =IF(E9<=(TODAY()+F9),"Send notification to supplier","No actions") -> Send notification to supplier | AC9: =IF((E9-D9)>720,W9>0, "No actions") -> FALSE | AD9: 999999999 | AE9: 45597
A10: 10017179 | B10: =VLOOKUP(A10,'All vendors'!A:Z,2,0) -> Leidy Mildreth Tobar Pinilla | C10: MSA | D10: 22-07-2024 | E10: 45627 | F10: 30 | G10: =VLOOKUP(A10,'All vendors'!B:E,4,0) -> #N/A | H10: =VLOOKUP(A10,'All vendors'!B:E,3,0) -> #N/A | I10: COL-Bogotá | J10: =VLOOKUP(A10,'All vendors'!A:Z,13,0) -> 45776.351 | K10: MPA_COL-VEN_2024-034 | L10: Legal Services | M10: =VLOOKUP(A10,'All vendors'!A:Z,11,0) -> Leidy Mildreth Tobar Pinilla | N10: =VLOOKUP(A10,'All vendors'!A:Z,12,0) -> +573112131650 | O10: =VLOOKUP(A10,'All vendors'!A:Z,15,0) -> customproductoscreativos@gmail.com | P10: Julio Gallardo Rojas | Q10: Davivienda | R10: DEL MAR ABOGADOS ASOCIADOS LTDA | S10: Sin Observaciones | T10: 0 | U10: =T10/4000 -> 0 | V10: =VLOOKUP(A10,'All vendors'!A:Z,17,0) -> 85000 | W10: 0 | AD10: 85000 | AE10: 45627
A11: 10050645 | B11: =VLOOKUP(A11,'All vendors'!A:Z,2,0) -> Iquartil SAS | C11: Serv Agreem | D11: 41769 | E11: 45650 | F11: 30 | G11: =VLOOKUP(A11,'All vendors'!B:E,4,0) -> #N/A | H11: =VLOOKUP(A11,'All vendors'!B:E,3,0) -> #N/A | I11: COL-Bogotá | J11: No tiene ATC | K11: SC+2500/2024/127 | L11: Recolección de Datos | M11: =VLOOKUP(A11,'All vendors'!A:Z,11,0) -> Beatriz Helena Cuervo Amore | N11: =VLOOKUP(A11,'All vendors'!A:Z,12,0) -> +573102361652 | O11: =VLOOKUP(A11,'All vendors'!A:Z,15,0) -> Beatriz.cuervo@iquartil.net | P11: Julio Gallardo Rojas | Q11: Davivienda | R11: DEL MAR ABOGADOS ASOCIADOS LTDA | S11: Sin Observaciones | T11: 0 | U11: =T11/4000 -> 0 | V11: =VLOOKUP(A11,'All vendors'!A:Z,17,0) -> 20000 | W11: 0 | Z11: =IF(H11>E11,"No actions","Update ATC") -> #N/A | AA11: =IF(E11<(TODAY()+90),"Send email to SC","No actions") -> Send email to SC | AB11: =IF(E11<=(TODAY()+F11),"Send notification to supplier","No actions") -> Send notification to supplier | AC11: =IF((E11-D11)>720,W11>0, "No actions") -> FALSE | AD11: 20000 | AE11: 45650
A12: 10000331 | B12: =VLOOKUP(A12,'All vendors'!A:Z,2,0) -> ATG Action Translation Group SAS | C12: MSA | D12: 44922 | E12: 45652 | F12: 30 | G12: =VLOOKUP(A12,'All vendors'!B:E,4,0) -> #N/A | H12: =VLOOKUP(A12,'All vendors'!B:E,3,0) -> #N/A | I12: COL-Bogotá | J12: =VLOOKUP(A12,'All vendors'!A:Z,13,0) -> 45775.112 | K12: MSA/2022/050 | L12: Translations | M12: =VLOOKUP(A12,'All vendors'!A:Z,11,0) -> Carlos Javier Rivera Rojas | N12: =VLOOKUP(A12,'All vendors'!A:Z,12,0) -> +573005630873 | O12: =VLOOKUP(A12,'All vendors'!A:Z,15,0) -> atgtraducciones@gmail.com | P12: Javier Rivera | Q12: Bancolombia | R12: ATG ACTION TRANSLATION GROUP SAS | S12: Sin Observaciones | T12: 0 | U12: =T12/4000 -> 0 | V12: =VLOOKUP(A12,'All vendors'!A:Z,17,0) -> 999999999 | W12: 0 | Z12: =IF(H12>E12,"No actions","Update ATC") -> #N/A | AA12: =IF(E12<(TODAY()+90),"Send email to SC","No actions") -> Send email to SC | AB12: =IF(E12<=(TODAY()+F12),"Send notification to supplier","No actions") -> Send notification to supplier | AC12: =IF((E12-D12)>720,W12>0, "No actions") -> FALSE | AD12: 999999999 | AE12: 45652
A13: 10022709 | B13: =VLOOKUP(A13,'All vendors'!A:Z,2,0) -> Blu Interpreter SAS | C13: MSA | D13: 44922 | E13: 45652 | F13: 30 | G13: =VLOOKUP(A13,'All vendors'!B:E,4,0) -> #N/A | H13: =VLOOKUP(A13,'All vendors'!B:E,3,0) -> #N/A | I13: COL-Bogotá | J13: =VLOOKUP(A13,'All vendors'!A:Z,13,0) -> 45835.716 | K13: MSA/2022/054 | L13: Translations | M13: =VLOOKUP(A13,'All vendors'!A:Z,11,0) -> Andrew Ebenezer Giraldo Pulido | N13: =VLOOKUP(A13,'All vendors'!A:Z,12,0) -> +573162062244 | O13: =VLOOKUP(A13,'All vendors'!A:Z,15,0) -> agiraldo@bluinterpreter.com | P13: Andrew Giraldo | Q13: Bancolombia | R13: BLU INTERPRETER SAS | S13: Sin Observaciones | T13: 0 | U13: =T13/4000 -> 0 | V13: =VLOOKUP(A13,'All vendors'!A:Z,17,0) -> 999999999 | W13: 0 | Z13: =IF(H13>E13,"No actions","Update ATC") -> #N/A | AA13: =IF(E13<(TODAY()+90),"Send email to SC","No actions") -> Send email to SC | AB13: =IF(E13<=(TODAY()+F13),"Send notification to supplier","No actions") -> Send notification to supplier | AC13: =IF((E13-D13)>720,W13>0, "No actions") -> FALSE | AD13: 999999999 | AE13: 45652
A14: 10050877 | B14: =VLOOKUP(A14,'All vendors'!A:Z,2,0) -> Seguridad Atlas Ltd. | C14: Serv Agreem | D14: 45475 | E14: 45653 | F14: 30 | G14: =VLOOKUP(A14,'All vendors'!B:E,4,0) -> #N/A | H14: =VLOOKUP(A14,'All vendors'!B:E,3,0) -> #N/A | I14: COL-Bogotá | J14: =VLOOKUP(A14,'All vendors'!A:Z,13,0) -> 45800.205 | K14: SC+2500/2024/119 | L14: Sagrilaf | M14: =VLOOKUP(A14,'All vendors'!A:Z,11,0) -> Diana Christina Harrera Gomez | N14: =VLOOKUP(A14,'All vendors'!A:Z,12,0) -> +573186127209 | O14: =VLOOKUP(A14,'All vendors'!A:Z,15,0) -> 0 | P14: Andrew Giraldo | Q14: Bancolombia | R14: BLU INTERPRETER SAS | S14: Sin Observaciones | T14: 0 | U14: =T14/4000 -> 0 | V14: =VLOOKUP(A14,'All vendors'!A:Z,17,0) -> 20000 | W14: 0 | AD14: 20000 | AE14: 45653
A15: 10005464 | B15: =VLOOKUP(A15,'All vendors'!A:Z,2,0) -> Telecomunicaciones TPB C.A. | C15: Serv Agreem | D15: 45474 | E15: 45657 | F15: 15 | G15: =VLOOKUP(A15,'All vendors'!B:E,4,0) -> #N/A | H15: =VLOOKUP(A15,'All vendors'!B:E,3,0) -> #N/A | I15: VEN-San Cristobal | J15: No tiene ATC | K15: SsC-2500/COL-VEN/2024/063 | L15: Internet Services | M15: =VLOOKUP(A15,'All vendors'!A:Z,11,0) -> Miguel Angel Rodriguez | N15: =VLOOKUP(A15,'All vendors'!A:Z,12,0) -> +584120584358 | O15: =VLOOKUP(A15,'All vendors'!A:Z,15,0) -> GestionTPB@colombiaconexiones.com | S15: Tope: 2.499 USD | T15: NA | U15: 0 | V15: =VLOOKUP(A15,'All vendors'!A:Z,17,0) -> 2400 | W15: 0 | Z15: =IF(H15>E15,"No actions","Update ATC") -> #N/A | AA15: =IF(E15<(TODAY()+90),"Send email to SC","No actions") -> Send email to SC | AB15: =IF(E15<=(TODAY()+F15),"Send notification to supplier","No actions") -> Send notification to supplier | AC15: =IF((E15-D15)>720,W15>0, "No actions") -> No actions | AD15: 2400 | AE15: 45657
A16: 10052988 | B16: =VLOOKUP(A16,'All vendors'!A:Z,2,0) -> Diana Cecilia Navarrete Canchón | C16: Serv Agreem | D16: 45570 | E16: 45657 | F16: 30 | G16: =VLOOKUP(A16,'All vendors'!B:E,4,0) -> #N/A | H16: =VLOOKUP(A16,'All vendors'!B:E,3,0) -> #N/A | I16: COL-Bogotá | J16: No tiene ATC | K16: SsC+2500_COL-VEN_2024_135 | L16: Nutrition Consultants | M16: =VLOOKUP(A16,'All vendors'!A:Z,11,0) -> Diana Cecilia Navarrete Canchón | N16: =VLOOKUP(A16,'All vendors'!A:Z,12,0) -> +573196743603 | O16: dcnavarretec08@gmail.com | S16: Tope:19000 USD | T16: NA | U16: 0 | V16: =VLOOKUP(A16,'All vendors'!A:Z,17,0) -> 19000 | W16: 0 | AD16: 19000 | AE16: 45657
A17: 10000333 | B17: =VLOOKUP(A17,'All vendors'!A:Z,2,0) -> Blanco Santana Montiel & Rincón | C17: Serv Agreem | D17: 45293 | E17: 45658 | F17: 30 | G17: =VLOOKUP(A17,'All vendors'!B:E,4,0) -> #N/A | H17: =VLOOKUP(A17,'All vendors'!B:E,3,0) -> #N/A | I17: VEN-Caracas | J17: =VLOOKUP(A17,'All vendors'!A:Z,13,0) -> 45867.716 | K17: SC+2500/2023/074 | L17: Legal Services | M17: =VLOOKUP(A17,'All vendors'!A:Z,11,0) -> Maria Alejandra Blanco Blanco | N17: =VLOOKUP(A17,'All vendors'!A:Z,12,0) -> +5824242506417 | O17: =VLOOKUP(A17,'All vendors'!A:Z,15,0) -> mablanco@bsmr.com.ve | Q17: Banesco S.A | R17: Blanco, Santana, Montiel & Rincòn Abogados | S17: Tope: 20.000 USD | T17: NA | U17: 0 | V17: =VLOOKUP(A17,'All vendors'!A:Z,17,0) -> 999999999 | W17: 0 | Z17: =IF(H17>E17,"No actions","Update ATC") -> #N/A | AA17: =IF(E17<(TODAY()+90),"Send email to SC","No actions") -> Send email to SC | AB17: =IF(E17<=(TODAY()+F17),"Send notification to supplier","No actions") -> Send notification to supplier | AC17: =IF((E17-D17)>720,W17>0, "No actions") -> No actions | AD17: 999999999 | AE17: 45658
A18: 10048679 | B18: =VLOOKUP(A18,'All vendors'!A:Z,2,0) -> Libia Johanna Leon Talero | C18: Serv Agreem | D18: 45297 | E18: 45662 | F18: 30 | G18: =VLOOKUP(A18,'All vendors'!B:E,4,0) -> #N/A | H18: =VLOOKUP(A18,'All vendors'!B:E,3,0) -> #N/A | I18: COL-Bogotá | J18: No tiene ATC | K18: SsC-2500-2024-041 | L18: English class Services | M18: =VLOOKUP(A18,'All vendors'!A:Z,11,0) -> Libia Johanna Leon Talero | N18: =VLOOKUP(A18,'All vendors'!A:Z,12,0) -> +573183028399 | O18: =VLOOKUP(A18,'All vendors'!A:Z,15,0) -> libilibileontalero@gmail.com | P18: Mercedez Espinoza | S18: Tope: 9.996.000 COP | T18: 0 | U18: =T18/4000 -> 0 | V18: =VLOOKUP(A18,'All vendors'!A:Z,17,0) -> 2450 | W18: 0 | AD18: 2450 | AE18: 45662
A19: 10013314 | B19: =VLOOKUP(A19,'All vendors'!A:Z,2,0) -> Transporte & Inversiones Filinto Gonzalez dba Filinto Antonio González Silva | C19: Serv Agreem | D19: 44935 | E19: 45666 | F19: 30 | G19: =VLOOKUP(A19,'All vendors'!B:E,4,0) -> #N/A | H19: =VLOOKUP(A19,'All vendors'!B:E,3,0) -> #N/A | I19: VEN-Maracaibo | J19: =VLOOKUP(A19,'All vendors'!A:Z,13,0) -> 45755.594 | K19: SC+2500/2023/065 | L19: Transportation | M19: =VLOOKUP(A19,'All vendors'!A:Z,11,0) -> Filinto Antonio González Silva | N19: =VLOOKUP(A19,'All vendors'!A:Z,12,0) -> +584122622049 | O19: =VLOOKUP(A19,'All vendors'!A:Z,15,0) -> Filintogonzalez1@hotmail.com | P19: Filinto Antonio Gonzalez | Q19: Bank of America | R19: Filinto Antonio Gonzalez | S19: Tope: 20.000 USD | T19: NA | U19: 0 | V19: =VLOOKUP(A19,'All vendors'!A:Z,17,0) -> 50000 | W19: 0 | Z19: =IF(H19>E19,"No actions","Update ATC") -> #N/A | AA19: =IF(E19<(TODAY()+90),"Send email to SC","No actions") -> Send email to SC | AB19: =IF(E19<=(TODAY()+F19),"Send notification to supplier","No actions") -> Send notification to supplier | AC19: =IF((E19-D19)>720,W19>0, "No actions") -> FALSE | AD19: 50000 | AE19: 45666
A20: 10048646 | B20: =VLOOKUP(A20,'All vendors'!A:Z,2,0) -> Servicios & Servicios Integrales s.a.s | C20: Serv Agreem | D20: 45308 | E20: 45673 | F20: 30 | G20: =VLOOKUP(A20,'All vendors'!B:E,4,0) -> #N/A | H20: =VLOOKUP(A20,'All vendors'!B:E,3,0) -> #N/A | I20: COL-Bogotá | J20: No tiene ATC | K20: SsC-2500-2024-042 | L20: Sanitation Services | M20: =VLOOKUP(A20,'All vendors'!A:Z,11,0) -> Alexandra Panqueva Espinoza | N20: =VLOOKUP(A20,'All vendors'!A:Z,12,0) -> +573183498423 | O20: =VLOOKUP(A20,'All vendors'!A:Z,15,0) -> alexandra.panqueva@prohygiene.com | P20: Mercedez Espinoza | S20: Tope: 9.996.000 COP | T20: 0 | U20: =T20/4000 -> 0 | V20: =VLOOKUP(A20,'All vendors'!A:Z,17,0) -> 2499 | W20: 0 | Z20: =IF(H20>E20,"No actions","Update ATC") -> #N/A | AA20: =IF(E20<(TODAY()+90),"Send email to SC","No actions") -> Send email to SC | AB20: =IF(E20<=(TODAY()+F20),"Send notification to supplier","No actions") -> Send notification to supplier | AC20: =IF((E20-D20)>720,W20>0, "No actions") -> No actions | AD20: 2499 | AE20: 45673
A21: 10026777 | B21: =VLOOKUP(A21,'All vendors'!A:Z,2,0) -> DATASAFECOLOMBIA LIMITADA | C21: Serv Agreem | D21: 45315 | E21: 45680 | F21: 30 | G21: =VLOOKUP(A21,'All vendors'!B:E,4,0) -> #N/A | H21: =VLOOKUP(A21,'All vendors'!B:E,3,0) -> #N/A | I21: COL-Bogotá | J21: No tiene ATC | K21: SsC-2500-2022-016 | L21: Office Services | M21: =VLOOKUP(A21,'All vendors'!A:Z,11,0) -> Gustavo Ortiz | N21: =VLOOKUP(A21,'All vendors'!A:Z,12,0) -> +573234365413 | O21: =VLOOKUP(A21,'All vendors'!A:Z,15,0) -> gerencia@datasafecolombia.com | P21: Adriana Villa | Q21: Davivienda | R21: Data Safe Colombia LTDA | S21: Tope: 2.499 USD | T21: 0 | U21: =T21/4000 -> 0 | V21: =VLOOKUP(A21,'All vendors'!A:Z,17,0) -> 2499 | W21: 0 | Z21: =IF(H21>E21,"No actions","Update ATC") -> #N/A | AA21: =IF(E21<(TODAY()+90),"Send email to SC","No actions") -> Send email to SC | AB21: =IF(E21<=(TODAY()+F21),"Send notification to supplier","No actions") -> Send notification to supplier | AC21: =IF((E21-D21)>720,W21>0, "No actions") -> No actions | AD21: 2499 | AE21: 45680
A22: 10025130 | B22: =VLOOKUP(A22,'All vendors'!A:Z,2,0) -> Servicios De Profesionales En Limpieza, C.A. | C22: Serv Agreem | D22: 44958 | E22: 45687 | F22: 30 | G22: =VLOOKUP(A22,'All vendors'!B:E,4,0) -> #N/A | H22: =VLOOKUP(A22,'All vendors'!B:E,3,0) -> #N/A | I22: VEN-Maracaibo | J22: =VLOOKUP(A22,'All vendors'!A:Z,13,0) -> 45666.257 | K22: SC+2500/2023/066 | L22: Cleaning services | M22: =VLOOKUP(A22,'All vendors'!A:Z,11,0) -> Yoxely Josefina Gonzalez Almarza | N22: =VLOOKUP(A22,'All vendors'!A:Z,12,0) -> +584246320253 | O22: =VLOOKUP(A22,'All vendors'!A:Z,15,0) -> Info@Seprolimca.com | P22: Yoxely Josefina Gonzalez | Q22: Well Fargo | R22: SEPROLIMCALLC | S22: Tope: 20.000 USD | T22: NA | U22: 0 | V22: =VLOOKUP(A22,'All vendors'!A:Z,17,0) -> 19000 | W22: 0 | Z22: =IF(H22>E22,"No actions","Update ATC") -> #N/A | AA22: =IF(E22<(TODAY()+90),"Send email to SC","No actions") -> Send email to SC | AB22: =IF(E22<=(TODAY()+F22),"Send notification to supplier","No actions") -> Send notification to supplier | AC22: =IF((E22-D22)>720,W22>0, "No actions") -> FALSE | AD22: 19000 | AE22: 45687
A23: 10027388 | B23: Gestora Estratégica Colombia S.A.S | C23: Serv Agreem | D23: 45323 | E23: 45688 | F23: 30 | G23: =VLOOKUP(A23,'All vendors'!B:E,4,0) -> #N/A | H23: =VLOOKUP(A23,'All vendors'!B:E,3,0) -> #N/A | I23: COL-Bogotá | J23: =VLOOKUP(A23,'All vendors'!A:Z,13,0) -> 45714.65 | K23: SC+2500/2024/110 | L23: Recargas de líneas telefónicas | M23: =VLOOKUP(A23,'All vendors'!A:Z,11,0) -> Yeny Andrea Vasquez Gutierrez | N23: =VLOOKUP(A23,'All vendors'!A:Z,12,0) -> +573112104884 | O23: =VLOOKUP(A23,'All vendors'!A:Z,15,0) -> administracion@gestrategica.com.co | P23: Mercedez Espinoza | S23: Tope: 20.000 USD | T23: 0 | U23: =T23/4000 -> 0 | V23: =VLOOKUP(A23,'All vendors'!A:Z,17,0) -> 999999999 | W23: 0 | AD23: 999999999 | AE23: 45688
A24: 10049307 | B24: =VLOOKUP(A24,'All vendors'!A:Z,2,0) -> Claudia Patricia Alvarez Ayure | C24: Serv Agreem | D24: 45323 | E24: 45323 | F24: 30 | G24: =VLOOKUP(A24,'All vendors'!B:E,4,0) -> #N/A | H24: =VLOOKUP(A24,'All vendors'!B:E,3,0) -> #N/A | I24: COL-Bogotá | J24: No tiene ATC | K24: SsC-2500-2024-043 | L24: English class Services | M24: =VLOOKUP(A24,'All vendors'!A:Z,11,0) -> Claudia Patricia Alvarez Ayure | N24: =VLOOKUP(A24,'All vendors'!A:Z,12,0) -> +573115953085 | O24: =VLOOKUP(A24,'All vendors'!A:Z,15,0) -> pattalvarez@gmail.com | S24: Tope:19000 USD | T24: NA | U24: 0 | V24: =VLOOKUP(A24,'All vendors'!A:Z,17,0) -> 19000 | W24: 0 | AD24: 19000 | AE24: 45323
A25: 10003142 | B25: =VLOOKUP(A25,'All vendors'!A:Z,2,0) -> Gestor Consultores S.A.S. | C25: MSA | D25: 44963 | E25: 45694 | F25: 30 | G25: =VLOOKUP(A25,'All vendors'!B:E,4,0) -> #N/A | H25: =VLOOKUP(A25,'All vendors'!B:E,3,0) -> #N/A | I25: COL-Bogotá | J25: =VLOOKUP(A25,'All vendors'!A:Z,13,0) -> 45659.677 | K25: MSA/2022/052 | L25: Coaching Services | M25: =VLOOKUP(A25,'All vendors'!A:Z,11,0) -> Juan Ricardo Orduz Garcia | N25: =VLOOKUP(A25,'All vendors'!A:Z,12,0) -> +573153872966 | O25: =VLOOKUP(A25,'All vendors'!A:Z,15,0) -> juano@gestorconsultores.com | P25: Juan Orduz | Q25: itau | R25: Gestor Consultores SAS | S25: Tiene una enmienda del 2024 | T25: 0 | U25: =T25/4000 -> 0 | V25: =VLOOKUP(A25,'All vendors'!A:Z,17,0) -> 999999999 | W25: 0 | Z25: =IF(H25>E25,"No actions","Update ATC") -> #N/A | AA25: =IF(E25<(TODAY()+90),"Send email to SC","No actions") -> Send email to SC | AB25: =IF(E25<=(TODAY()+F25),"Send notification to supplier","No actions") -> Send notification to supplier | AC25: =IF((E25-D25)>720,W25>0, "No actions") -> FALSE | AD25: 999999999 | AE25: 45694
A26: 10022620 | B26: =VLOOKUP(A26,'All vendors'!A:Z,2,0) -> B&B Consultoría y Asesoría Empresarial SAS | C26: MSA | D26: 44964 | E26: 45694 | F26: 30 | G26: =VLOOKUP(A26,'All vendors'!B:E,4,0) -> #N/A | H26: =VLOOKUP(A26,'All vendors'!B:E,3,0) -> #N/A | I26: COL-Bogotá | J26: =VLOOKUP(A26,'All vendors'!A:Z,13,0) -> 45654.504 | K26: MSA/2022/053 | L26: Coaching Services | M26: =VLOOKUP(A26,'All vendors'!A:Z,11,0) -> William Yesid Bejarano Cano | N26: =VLOOKUP(A26,'All vendors'!A:Z,12,0) -> +573118990147 | O26: =VLOOKUP(A26,'All vendors'!A:Z,15,0) -> yesid.bejarano@gmail.com | P26: William Yesid Bejarano | Q26: Bancolombia | R26: B&B CONSULTORIA Y ASESORIA EMPRESARIAL SAS | S26: Tiene una enmienda del 2024 | T26: 0 | U26: =T26/4000 -> 0 | V26: =VLOOKUP(A26,'All vendors'!A:Z,17,0) -> 999999999 | W26: 0 | Z26: =IF(H26>E26,"No actions","Update ATC") -> #N/A | AA26: =IF(E26<(TODAY()+90),"Send email to SC","No actions") -> Send email to SC | AB26: =IF(E26<=(TODAY()+F26),"Send notification to supplier","No actions") -> Send notification to supplier | AC26: =IF((E26-D26)>720,W26>0, "No actions") -> FALSE | AD26: 999999999 | AE26: 45694
A27: 10048253 | B27: Arckideas S.A.S. | C27: Serv Agreem | D27: 45338 | E27: 45703 | F27: 30 | G27: =VLOOKUP(A27,'All vendors'!B:E,4,0) -> #N/A | H27: =VLOOKUP(A27,'All vendors'!B:E,3,0) -> #N/A | I27: COL-Cúcuta | J27: No tiene ATC | K27: SsC-2500-2024-039 | L27: Parking Services | M27: =VLOOKUP(A27,'All vendors'!A:Z,11,0) -> Paola Peñaloza | N27: =VLOOKUP(A27,'All vendors'!A:Z,12,0) -> +573206712095 | O27: =VLOOKUP(A27,'All vendors'!A:Z,15,0) -> arckideasparkingservices@gmail.com | P27: William Yesid Bejarano | Q27: Bancolombia | R27: B&B CONSULTORIA Y ASESORIA EMPRESARIAL SAS | S27: Tope $5.000.000 COP | T27: 0 | U27: =T27/4000 -> 0 | V27: =VLOOKUP(A27,'All vendors'!A:Z,17,0) -> 2400 | W27: 0 | Z27: =IF(H27>E27,"No actions","Update ATC") -> #N/A | AA27: =IF(E27<(TODAY()+90),"Send email to SC","No actions") -> Send email to SC | AB27: =IF(E27<=(TODAY()+F27),"Send notification to supplier","No actions") -> Send notification to supplier | AC27: =IF((E27-D27)>720,W27>0, "No actions") -> No actions | AD27: 2400 | AE27: 45703
A28: 10000428 | B28: =VLOOKUP(A28,'All vendors'!A:Z,2,0) -> Rastrack SAS | C28: Serv Agreem | D28: 44974 | E28: 45704 | F28: 30 | G28: =VLOOKUP(A28,'All vendors'!B:E,4,0) -> #N/A | H28: =VLOOKUP(A28,'All vendors'!B:E,3,0) -> #N/A | I28: COL-Bogotá | J28: =VLOOKUP(A28,'All vendors'!A:Z,13,0) -> 45838.219 | K28: SC+2500/2023/063 | L28: Security Services | M28: =VLOOKUP(A28,'All vendors'!A:Z,11,0) -> Liliana Trujillo | N28: =VLOOKUP(A28,'All vendors'!A:Z,12,0) -> +573173801025 | O28: =VLOOKUP(A28,'All vendors'!A:Z,15,0) -> negociosespeciales@rastrack.com | P28: David Velazquez | Q28: Bancolombia | R28: Rastrack SAS | S28: Tope: 20.000 USD | T28: 0 | U28: =T28/4000 -> 0 | V28: =VLOOKUP(A28,'All vendors'!A:Z,17,0) -> 999999999 | W28: 0 | Z28: =IF(H28>E28,"No actions","Update ATC") -> #N/A | AA28: =IF(E28<(TODAY()+90),"Send email to SC","No actions") -> Send email to SC | AB28: =IF(E28<=(TODAY()+F28),"Send notification to supplier","No actions") -> Send notification to supplier | AC28: =IF((E28-D28)>720,W28>0, "No actions") -> FALSE | AD28: 999999999 | AE28: 45704
A29: 10045039 | B29: =VLOOKUP(A29,'All vendors'!A:Z,2,0) -> Grupo Polka S.A.S | C29: Serv Agreem | D29: 45348 | E29: 45713 | F29: 30 | G29: =VLOOKUP(A29,'All vendors'!B:E,4,0) -> #N/A | H29: =VLOOKUP(A29,'All vendors'!B:E,3,0) -> #N/A | I29: COL-Bogotá | J29: No tiene ATC | K29: SsC-2500-2024-044 | L29: Refrigerios | M29: =VLOOKUP(A29,'All vendors'!A:Z,11,0) -> Natalia Bohorquez Perry | N29: =VLOOKUP(A29,'All vendors'!A:Z,12,0) -> +573213338434 | O29: =VLOOKUP(A29,'All vendors'!A:Z,15,0) -> pedidos@polkadotpasteleria.com | P29: David Velazquez | Q29: Bancolombia | R29: Rastrack SAS | S29: Tope: 9.000.000 COP | T29: 0 | U29: =T29/4000 -> 0 | V29: =VLOOKUP(A29,'All vendors'!A:Z,17,0) -> 2499 | W29: 0 | Z29: =IF(H29>E29,"No actions","Update ATC") -> #N/A | AA29: =IF(E29<(TODAY()+90),"Send email to SC","No actions") -> Send email to SC | AB29: =IF(E29<=(TODAY()+F29),"Send notification to supplier","No actions") -> Send notification to supplier | AC29: =IF((E29-D29)>720,W29>0, "No actions") -> No actions | AD29: 2499 | AE29: 45713
A30: 10049717 | B30: =VLOOKUP(A30,'All vendors'!A:Z,2,0) -> Salud Ocupacional Horizonte LTDA | C30: Serv Agreem | D30: 45352 | E30: 45716 | F30: 30 | G30: =VLOOKUP(A30,'All vendors'!B:E,4,0) -> #N/A | H30: =VLOOKUP(A30,'All vendors'!B:E,3,0) -> #N/A | I30: COL-Bogotá | J30: =VLOOKUP(A30,'All vendors'!A:Z,13,0) -> 45708.254 | K30: SC+2500/2024/113 | L30: Health Services | M30: =VLOOKUP(A30,'All vendors'!A:Z,11,0) -> Nicolás Villamizar | N30: =VLOOKUP(A30,'All vendors'!A:Z,12,0) -> +573160414402 | O30: =VLOOKUP(A30,'All vendors'!A:Z,15,0) -> nicolas.villamizar@gsh.com.co | P30: David Velazquez | Q30: Bancolombia | R30: Rastrack SAS | S30: Sin Observaciones | T30: 0 | U30: =T30/4000 -> 0 | V30: =VLOOKUP(A30,'All vendors'!A:Z,17,0) -> 20000 | W30: 0 | AD30: 20000 | AE30: 45716
A31: 10019523 | B31: =VLOOKUP(A31,'All vendors'!A:Z,2,0) -> Suarez Silva & Asociados | C31: Serv Agreem | D31: 44866 | E31: 45716 | F31: 30 | I31: VEN-Caracas | J31: =VLOOKUP(A31,'All vendors'!A:Z,13,0) -> 45609.292 | K31: SC+2500/2024/117 | L31: Nomina | M31: =VLOOKUP(A31,'All vendors'!A:Z,11,0) -> Alejandra Suarez Silva | N31: =VLOOKUP(A31,'All vendors'!A:Z,12,0) -> +584144662227 | O31: =VLOOKUP(A31,'All vendors'!A:Z,15,0) -> Suarezsilvaasociados@gmail.com | P31: David Velazquez | Q31: Bancolombia | R31: Rastrack SAS | S31: Sin Observaciones | T31: NA | U31: 0 | V31: =VLOOKUP(A31,'All vendors'!A:Z,17,0) -> 999999999 | W31: 0 | AD31: 999999999 | AE31: 45716
A32: 10025027 | B32: =VLOOKUP(A32,'All vendors'!A:Z,2,0) -> Matteria S.A.S | C32: Serv Agreem | D32: 44986 | E32: 45722 | F32: 5 | G32: =VLOOKUP(A32,'All vendors'!B:E,4,0) -> #N/A | H32: =VLOOKUP(A32,'All vendors'!B:E,3,0) -> #N/A | I32: COL-Bogotá | J32: =VLOOKUP(A32,'All vendors'!A:Z,13,0) -> 45659.684 | K32: SC+2500/2023/068 | L32: Consultant | M32: =VLOOKUP(A32,'All vendors'!A:Z,11,0) -> Fernanda Forero Barbosa | N32: =VLOOKUP(A32,'All vendors'!A:Z,12,0) -> 0 | O32: =VLOOKUP(A32,'All vendors'!A:Z,15,0) -> 0 | P32: Fernanda Forero | S32: Tope: 20.000 USD | T32: 0 | U32: =T32/4000 -> 0 | V32: =VLOOKUP(A32,'All vendors'!A:Z,17,0) -> 999999999 | W32: 0 | Z32: =IF(H32>E32,"No actions","Update ATC") -> #N/A | AA32: =IF(E32<(TODAY()+90),"Send email to SC","No actions") -> Send email to SC | AB32: =IF(E32<=(TODAY()+F32),"Send notification to supplier","No actions") -> No actions | AC32: =IF((E32-D32)>720,W32>0, "No actions") -> FALSE | AD32: 999999999 | AE32: 45722
A33: 10050010 | B33: =VLOOKUP(A33,'All vendors'!A:Z,2,0) -> Empresa de Transporte Radio Taxi Radio SA | C33: Serv Agreem | D33: 45369 | E33: 45733 | F33: 30 | I33: COL-Cúcuta | J33: =VLOOKUP(A33,'All vendors'!A:Z,13,0) -> 45722.684 | K33: SC+2500/2024/115 | L33: Transportation | M33: =VLOOKUP(A33,'All vendors'!A:Z,11,0) -> Gloria Yaneth Jaramillo Garcia | N33: =VLOOKUP(A33,'All vendors'!A:Z,12,0) -> +573212925177 | O33: =VLOOKUP(A33,'All vendors'!A:Z,15,0) -> radiotaxiradio1984@gmail.com | S33: Tope: 20.000 USD | T33: 0 | U33: =T33/4000 -> 0 | V33: =VLOOKUP(A33,'All vendors'!A:Z,17,0) -> 19000 | W33: 0 | AC33: =IF((E33-D33)>720,W33>0, "No actions") -> No actions | AD33: 19000 | AE33: 45733
A34: 10017030 | B34: =VLOOKUP(A34,'All vendors'!A:Z,2,0) -> Real Time Security (Colombia,Peru) SAS | C34: Serv Agreem | D34: 44640 | E34: 45735 | F34: 30 | G34: =VLOOKUP(A34,'All vendors'!B:E,4,0) -> #N/A | H34: =VLOOKUP(A34,'All vendors'!B:E,3,0) -> #N/A | I34: COL-Bogotá | J34: =VLOOKUP(A34,'All vendors'!A:Z,13,0) -> 45688.271 | K34: SsC-2500-2020-004 | L34: Security Services | M34: =VLOOKUP(A34,'All vendors'!A:Z,11,0) -> Christian Javier Estupiñan Córdoba | N34: =VLOOKUP(A34,'All vendors'!A:Z,12,0) -> +573202067849 | O34: =VLOOKUP(A34,'All vendors'!A:Z,15,0) -> cestupinan@realtimesecurity-colombia.com | P34: Christian Javier Estupiñan Cordoba | Q34: Bancolombia | R34: Real Time Security Colombia SAS | S34: El contrato se extendió y se modificó la cobertura, será solo para Colombia . | T34: 0 | U34: =T34/4000 -> 0 | V34: =VLOOKUP(A34,'All vendors'!A:Z,17,0) -> 50000 | W34: 0 | Z34: =IF(H34>E34,"No actions","Update ATC") -> #N/A | AA34: =IF(E34<(TODAY()+90),"Send email to SC","No actions") -> Send email to SC | AB34: =IF(E34<=(TODAY()+F34),"Send notification to supplier","No actions") -> Send notification to supplier | AC34: =IF((E34-D34)>720,W34>0, "No actions") -> FALSE | AD34: 50000 | AE34: 45735
A35: 10050195 | B35: =VLOOKUP(A35,'All vendors'!A:Z,2,0) -> Pluxee Beneficios e Incentivos, C.A. | C35: Serv Agreem | D35: 45378 | E35: 45742 | F35: 30 | G35: =VLOOKUP(A35,'All vendors'!B:E,4,0) -> #N/A | H35: =VLOOKUP(A35,'All vendors'!B:E,3,0) -> #N/A | I35: VEN-Caracas | J35: =VLOOKUP(A35,'All vendors'!A:Z,13,0) -> 45743.299 | K35: Contrato del Proveedor | L35: Tarjeta de Alimentación | M35: =VLOOKUP(A35,'All vendors'!A:Z,11,0) -> Vanessa Sandoval | N35: =VLOOKUP(A35,'All vendors'!A:Z,12,0) -> +584241623183 | O35: =VLOOKUP(A35,'All vendors'!A:Z,15,0) -> Vanessa.sandoval@pluxeegroup.com | P35: Margarita Restrepo | Q35: Bancolombia | R35: Agencia de Viajes y Turismo AVIATUR SAS | S35: Sin Observaciones | T35: NA | U35: 0 | V35: =VLOOKUP(A35,'All vendors'!A:Z,17,0) -> 19000 | W35: 0 | AD35: 19000 | AE35: 45742
A36: 10049688 | B36: =VLOOKUP(A36,'All vendors'!A:Z,2,0) -> Servicios Colomven S.A.S | C36: Serv Agreem | D36: 45317 | E36: 45747 | F36: 30 | G36: =VLOOKUP(A36,'All vendors'!B:E,4,0) -> #N/A | H36: =VLOOKUP(A36,'All vendors'!B:E,3,0) -> #N/A | I36: COL-Cúcuta | J36: =VLOOKUP(A36,'All vendors'!A:Z,13,0) -> 45707.271 | K36: SC+2500/2024/111 | L36: Cleaning services | M36: =VLOOKUP(A36,'All vendors'!A:Z,11,0) -> Jose Reinel Tami | N36: =VLOOKUP(A36,'All vendors'!A:Z,12,0) -> +573106495406 | O36: =VLOOKUP(A36,'All vendors'!A:Z,15,0) -> servicioscolomvensas@gmail.com | P36: Mariana Saenz | Q36: Banco de Bogotá | R36: Corporación Vínculos | S36: Tope 15.000.000 COP. Se realizara renovación | T36: 0 | U36: =T36/4000 -> 0 | V36: =VLOOKUP(A36,'All vendors'!A:Z,17,0) -> 4000 | W36: 0 | Z36: =IF(H36>E36,"No actions","Update ATC") -> #N/A | AA36: =IF(E36<(TODAY()+90),"Send email to SC","No actions") -> Send email to SC | AB36: =IF(E36<=(TODAY()+F36),"Send notification to supplier","No actions") -> No actions | AC36: =IF((E36-D36)>720,W36>0, "No actions") -> No actions | AD36: 4000 | AE36: 45747
A37: 10000391 | B37: =VLOOKUP(A37,'All vendors'!A:Z,2,0) -> Agencia De Viajes Y Turismo Aviatur SAS | C37: MSA | D37: 45017 | E37: 45747 | F37: 30 | G37: =VLOOKUP(A37,'All vendors'!B:E,4,0) -> #N/A | H37: =VLOOKUP(A37,'All vendors'!B:E,3,0) -> #N/A | I37: COL-Bogotá | J37: =VLOOKUP(A37,'All vendors'!A:Z,13,0) -> 45848.441 | K37: MSA/2022/051 | L37: Travel Agency | M37: =VLOOKUP(A37,'All vendors'!A:Z,11,0) -> Margarita Restrepo | N37: =VLOOKUP(A37,'All vendors'!A:Z,12,0) -> +573153493584 | O37: =VLOOKUP(A37,'All vendors'!A:Z,15,0) -> magarita.restrepo@aviatur.com | P37: Margarita Restrepo | Q37: Bancolombia | R37: Agencia de Viajes y Turismo AVIATUR SAS | S37: Sin Observaciones | T37: 0 | U37: =T37/4000 -> 0 | V37: =VLOOKUP(A37,'All vendors'!A:Z,17,0) -> 999999999 | W37: 0 | Z37: =IF(H37>E37,"No actions","Update ATC") -> #N/A | AA37: =IF(E37<(TODAY()+90),"Send email to SC","No actions") -> Send email to SC | AB37: =IF(E37<=(TODAY()+F37),"Send notification to supplier","No actions") -> No actions | AC37: =IF((E37-D37)>720,W37>0, "No actions") -> FALSE | AD37: 999999999 | AE37: 45747
A38: 10001345 | B38: =VLOOKUP(A38,'All vendors'!A:Z,2,0) -> Movlife S.A.S | C38: MSA | D38: 44652 | E38: 45747 | F38: 30 | G38: =VLOOKUP(A38,'All vendors'!B:E,4,0) -> #N/A | H38: =VLOOKUP(A38,'All vendors'!B:E,3,0) -> #N/A | I38: COL-Bogotá | J38: =VLOOKUP(A38,'All vendors'!A:Z,13,0) -> 45709.487 | K38: MSA/2022/037 | L38: Transportation | M38: =VLOOKUP(A38,'All vendors'!A:Z,11,0) -> Astrid Melissa Gómez Flórez | N38: =VLOOKUP(A38,'All vendors'!A:Z,12,0) -> +573123103269 | O38: =VLOOKUP(A38,'All vendors'!A:Z,15,0) -> melissa.gomez@movlife.co | P38: Claudia Patricia Flórez | Q38: Davivienda | R38: Movlife SAS | S38: Tiene una enmienda del 2024 | T38: 0 | U38: =T38/4000 -> 0 | V38: =VLOOKUP(A38,'All vendors'!A:Z,17,0) -> 999999999 | W38: 0 | Z38: =IF(H38>E38,"No actions","Update ATC") -> #N/A | AA38: =IF(E38<(TODAY()+90),"Send email to SC","No actions") -> Send email to SC | AB38: =IF(E38<=(TODAY()+F38),"Send notification to supplier","No actions") -> No actions | AC38: =IF((E38-D38)>720,W38>0, "No actions") -> FALSE | AD38: 999999999 | AE38: 45747
A39: 10050094 | B39: =VLOOKUP(A39,'All vendors'!A:Z,2,0) -> Graficalez SAS | C39: Purch Agreem | D39: 45383 | E39: 45747 | F39: 30 | G39: =VLOOKUP(A39,'All vendors'!B:E,4,0) -> #N/A | H39: =VLOOKUP(A39,'All vendors'!B:E,3,0) -> #N/A | I39: COL-Bogotá | J39: =VLOOKUP(A39,'All vendors'!A:Z,13,0) -> 45735.493 | K39: SC+2500/2024/112 | L39: Visibility | M39: =VLOOKUP(A39,'All vendors'!A:Z,11,0) -> Francys Lizeth Gonzalez Castillo | N39: =VLOOKUP(A39,'All vendors'!A:Z,12,0) -> +573123107175 | O39: =VLOOKUP(A39,'All vendors'!A:Z,15,0) -> comercialgraficalez@gmail.com | P39: Claudia Patricia Flórez | Q39: Davivienda | R39: Movlife SAS | S39: Sin Observaciones | T39: 0 | U39: =T39/4000 -> 0 | V39: =VLOOKUP(A39,'All vendors'!A:Z,17,0) -> 19000 | W39: 0 | Z39: =IF(H39>E39,"No actions","Update ATC") -> #N/A | AA39: =IF(E39<(TODAY()+90),"Send email to SC","No actions") -> Send email to SC | AB39: =IF(E39<=(TODAY()+F39),"Send notification to supplier","No actions") -> No actions | AC39: =IF((E39-D39)>720,W39>0, "No actions") -> No actions | AD39: 19000 | AE39: 45747
A40: 10050034 | B40: =VLOOKUP(A40,'All vendors'!A:Z,2,0) -> Antonia Trinidad Herrera Chirinos | C40: Purch Agreem | D40: 45383 | E40: 45747 | F40: 30 | G40: =VLOOKUP(A40,'All vendors'!B:E,4,0) -> #N/A | H40: =VLOOKUP(A40,'All vendors'!B:E,3,0) -> #N/A | I40: COL-Bogotá | J40: No tiene ATC | K40: SsC-2500-2024-051 | L40: Refrigerios | M40: =VLOOKUP(A40,'All vendors'!A:Z,11,0) -> Antonia Trinidad Herrera Chirinos | N40: =VLOOKUP(A40,'All vendors'!A:Z,12,0) -> +573142103152 | O40: =VLOOKUP(A40,'All vendors'!A:Z,15,0) -> anthoniach1402@gmail.com | P40: Claudia Patricia Flórez | Q40: Davivienda | R40: Movlife SAS | S40: Sin Observaciones | T40: 0 | U40: =T40/4000 -> 0 | V40: =VLOOKUP(A40,'All vendors'!A:Z,17,0) -> 2400 | W40: 0 | Z40: =IF(H40>E40,"No actions","Update ATC") -> #N/A | AA40: =IF(E40<(TODAY()+90),"Send email to SC","No actions") -> Send email to SC | AB40: =IF(E40<=(TODAY()+F40),"Send notification to supplier","No actions") -> No actions | AC40: =IF((E40-D40)>720,W40>0, "No actions") -> No actions | AD40: 2400 | AE40: 45747
A41: 10000402 | B41: =VLOOKUP(A41,'All vendors'!A:Z,2,0) -> Tigers Job Ltda | C41: Serv Agreem | D41: 45383 | E41: 45747 | F41: 30 | G41: =VLOOKUP(A41,'All vendors'!B:E,4,0) -> #N/A | H41: =VLOOKUP(A41,'All vendors'!B:E,3,0) -> #N/A | I41: COL-Cúcuta | J41: =VLOOKUP(A41,'All vendors'!A:Z,13,0) -> 45654.532 | K41: SC+2500/2024/118 | L41: Private Security | M41: =VLOOKUP(A41,'All vendors'!A:Z,11,0) -> Angelica Guerrero Gonzalez | N41: =VLOOKUP(A41,'All vendors'!A:Z,12,0) -> +573152350459 | O41: =VLOOKUP(A41,'All vendors'!A:Z,15,0) -> comercial@tigerjob.com.co | P41: Maria del Carmen Delgado | Q41: Banco de Bogotá | R41: TIGERS JOB Ltda | S41: Sin Observaciones | T41: 0 | U41: =T41/4000 -> 0 | V41: =VLOOKUP(A41,'All vendors'!A:Z,17,0) -> 999999999 | W41: 0 | Y41: =IF(H41>E41,"No actions","Update ATC") -> #N/A | Z41: =IF(E41<(TODAY()+90),"Send email to SC","No actions") -> Send email to SC | AA41: =IF(E41<=(TODAY()+F41),"Send notification to supplier","No actions") -> No actions | AB41: =IF((E41-D41)>720,U41>0, "No actions") -> No actions | AD41: 999999999 | AE41: 45747
...

Sheet Contracted Suppliers_Closed
B1: Contracted Supplier Tracking Sheet
B3: COLOMBIA - VENEZUELA
A4: Vendor account | B4: Supplier name | C4: Type of contract | D4: Contract Start Date | E4: Contract End Date | F4: Notice date (days) | G4: ATC status | H4: ATC clearance expiration date | I4: Site | J4: ATC | K4: Contract Reference | L4: Category of Goods or Services | M4: Contact Person | N4: Contact Phone/Fax Numbers | O4: Contact Email Address | P4: Ownership or Leadership Information | Q4: Name of Financial Institution (for bank-to-bank transactations only) | R4: Name of Account Holder (for bank-to-bank transactations only) | S4: Notes | T4: TOPE EN DOLARES | U4: Valor Gastado | V4: Number of Amendments | W4: Valor gastado USD | Y4: ATC | Z4: Notification to SC | AA4: Notification to Supplier | AB4: Amendments
A5: 10016768 | B5: =VLOOKUP(A5,'All vendors'!A:Z,2,0) -> Comercializadora Surtiempresa SAS | C5: Purch Agreem | D5: 44846 | E5: 45574 | F5: 5 | G5: =VLOOKUP(A5,'All vendors'!B:E,4,0) -> #N/A | H5: =VLOOKUP(A5,'All vendors'!B:E,3,0) -> #N/A | I5: COL-Bogotá | J5: =VLOOKUP(A5,'All vendors'!A:Z,13,0) -> 45859.428 | K5: SC+2500/2022/041 | L5: Purchase of goods | M5: =VLOOKUP(A5,'All vendors'!A:Z,11,0) -> Yeymy Sánchez Suárez | N5: =VLOOKUP(A5,'All vendors'!A:Z,12,0) -> +573133175241 | O5: =VLOOKUP(A5,'All vendors'!A:Z,15,0) -> comercial@surtimpresa.com | P5: Yeymy Lucena Sánchez Suárez | Q5: Banco Caja Social | R5: Comercializadora Surtiempresa SAS | S5: Tope: 20.000 USD. Se realizara un proceso nuevo | T5: 20000 | U5: 56532751 | V5: 0 | W5: =VLOOKUP(A5,'All vendors'!A:Z,17,0) -> 999999999 | X5: 1 | AA5: =IF(H5>E5,"No actions","Update ATC") -> #N/A | AB5: =IF(E5<(TODAY()+90),"Send email to SC","No actions") -> Send email to SC | AC5: =IF(E5<=(TODAY()+F5),"Send notification to supplier","No actions") -> Send notification to supplier | AD5: =IF((E5-D5)>720,X5>0, "No actions") -> TRUE
A6: 10050145 | B6: =VLOOKUP(A6,'All vendors'!A:Z,2,0) -> Julio Bermudez | C6: Serv Agreem | D6: 45385 | E6: 45576 | F6: 30 | G6: =VLOOKUP(A6,'All vendors'!B:E,4,0) -> #N/A | H6: =VLOOKUP(A6,'All vendors'!B:E,3,0) -> #N/A | I6: VEN-Caracas | J6: =VLOOKUP(A6,'All vendors'!A:Z,13,0) -> 45740.678 | K6: Sin Numero | L6: Dotación | M6: =VLOOKUP(A6,'All vendors'!A:Z,11,0) -> Julio Bermudez | N6: =VLOOKUP(A6,'All vendors'!A:Z,12,0) -> +584120120225 | O6: =VLOOKUP(A6,'All vendors'!A:Z,15,0) -> intertono@hotmail.com | P6: Claudia Patricia Flórez | Q6: Davivienda | R6: Movlife SAS | S6: Tope: 6.912,05 USD. No se renovara | T6: 6912.05 | U6: 0 | V6: 0 | W6: =VLOOKUP(A6,'All vendors'!A:Z,17,0) -> 14000 | X6: 0
A7: 10036870 | B7: =VLOOKUP(A7,'All vendors'!A:Z,2,0) -> Comercializadora Femavi S.A.S. | C7: Purch Agreem | D7: 45189 | E7: 45554 | F7: 30 | G7: =VLOOKUP(A7,'All vendors'!B:E,4,0) -> #N/A | H7: =VLOOKUP(A7,'All vendors'!B:E,3,0) -> #N/A | I7: COL-Bogotá | J7: =VLOOKUP(A7,'All vendors'!A:Z,13,0) -> 45700.473 | K7: SC+2500/2023/101 | L7: POP goods | M7: =VLOOKUP(A7,'All vendors'!A:Z,11,0) -> Victor Bohada | N7: =VLOOKUP(A7,'All vendors'!A:Z,12,0) -> +573102924522 | O7: =VLOOKUP(A7,'All vendors'!A:Z,15,0) -> victorbohada@femavi.com.co | S7: Tope: 20.000 USD. El contrato terminará, hay dos contratos en firma para reemplazarlo | T7: 20000 | U7: =495000+17068735 -> 17563735 | V7: 0 | W7: =VLOOKUP(A7,'All vendors'!A:Z,17,0) -> 20000 | X7: 0 | AA7: =IF(H7>E7,"No actions","Update ATC") -> #N/A | AB7: =IF(E7<(TODAY()+90),"Send email to SC","No actions") -> Send email to SC | AC7: =IF(E7<=(TODAY()+F7),"Send notification to supplier","No actions") -> Send notification to supplier | AD7: =IF((E7-D7)>720,X7>0, "No actions") -> No actions
A8: 10002985 | B8: =VLOOKUP(A8,'All vendors'!A:Z,2,0) -> Interamericana De Auditores Y Consultores Ltda | C8: Serv Agreem | D8: 45447 | E8: 45510 | F8: 30 | G8: =VLOOKUP(A8,'All vendors'!B:E,4,0) -> #N/A | H8: =VLOOKUP(A8,'All vendors'!B:E,3,0) -> #N/A | I8: COL-Bogotá | J8: =VLOOKUP(A8,'All vendors'!A:Z,13,0) -> 45769.466 | K8: SC+2500/2024/123 | L8: Auditoria | M8: =VLOOKUP(A8,'All vendors'!A:Z,11,0) -> Jose Luis Cruz Blanco | N8: =VLOOKUP(A8,'All vendors'!A:Z,12,0) -> +573102986541 | O8: =VLOOKUP(A8,'All vendors'!A:Z,15,0) -> director@interamericana.co | P8: Edilberto Gordillo | S8: Tope: 11.904.750,00 COP. En proceso de renovación | T8: =11904750/4000 -> 2976.1875 | U8: 1980000 | V8: 0 | W8: =VLOOKUP(A8,'All vendors'!A:Z,17,0) -> 20000 | X8: 0 | AA8: =IF(H8>E8,"No actions","Update ATC") -> #N/A | AB8: =IF(E8<(TODAY()+90),"Send email to SC","No actions") -> Send email to SC | AC8: =IF(E8<=(TODAY()+F8),"Send notification to supplier","No actions") -> Send notification to supplier | AD8: =IF((E8-D8)>720,X8>0, "No actions") -> No actions
A9: 10026142 | B9: =VLOOKUP(A9,'All vendors'!A:Z,2,0) -> Institucion Prestadora de Servicios de Salud Domiciliarios Sanarte Clinica de Heridas y Ostomias S.A | C9: Serv Agreem | D9: 44977 | E9: 45341 | F9: 30 | G9: =VLOOKUP(A9,'All vendors'!B:E,4,0) -> #N/A | H9: =VLOOKUP(A9,'All vendors'!B:E,3,0) -> #N/A | I9: COL-Cúcuta | J9: =VLOOKUP(A9,'All vendors'!A:Z,13,0) -> 45329.129 | K9: SsC-2500//2023/023 | L9: Health ( Ambulance service) | M9: =VLOOKUP(A9,'All vendors'!A:Z,11,0) -> Beatriz Adriana Villamizar Sarmiento | N9: =VLOOKUP(A9,'All vendors'!A:Z,12,0) -> +575922778 | O9: =VLOOKUP(A9,'All vendors'!A:Z,15,0) -> ipssanarte@gmail.com | P9: Beatriz Villamizar | Q9: Bancolombia | R9: SANARTE SAS | S9: Dayana: se tramitará carta de culminación anticipada ya que este servicio de ambulancia no fue utilizado. Fecha finalización 19-02-2024 Y/O HASTA EL AGOTAMIENTO DE LOS RECURSOS Costo de los servicios: HASTA LA SUMA DE $4.000.000. A la fecha 26/01/2024 no se ha gastado nada. | T9: 0 | U9: 0 | V9: 0 | Y9: =IF(H9>E9,"No actions","Update ATC") -> #N/A | Z9: =IF(E9<(TODAY()+90),"Send email to SC","No actions") -> Send email to SC | AA9: =IF(E9<=(TODAY()+F9),"Send notification to supplier","No actions") -> Send notification to supplier | AB9: =IF((E9-D9)>720,V9>0, "No actions") -> No actions
A10: 10000522 | B10: =VLOOKUP(A10,'All vendors'!A:Z,2,0) -> Freedomcenter S.A.S | C10: Serv Agreem | D10: 45061 | E10: 45351 | F10: 5 | G10: =VLOOKUP(A10,'All vendors'!B:E,4,0) -> #N/A | H10: =VLOOKUP(A10,'All vendors'!B:E,3,0) -> #N/A | I10: COL-Bogotá | J10: =VLOOKUP(A10,'All vendors'!A:Z,13,0) -> 45810.038 | K10: SC+2500/2023/081 | L10: Education Data collection | M10: =VLOOKUP(A10,'All vendors'!A:Z,11,0) -> Olga Paola Vargas Lopez | N10: =VLOOKUP(A10,'All vendors'!A:Z,12,0) -> +573113751223 | O10: =VLOOKUP(A10,'All vendors'!A:Z,15,0) -> contacto@freedomcenter.com.co | S10: Waiver firmado | T10: 0 | U10: =28498506.75+107288496+135787002.75 -> 2.7157401e+08 | V10: 0 | Y10: =IF(H10>E10,"No actions","Update ATC") -> #N/A | Z10: =IF(E10<(TODAY()+90),"Send email to SC","No actions") -> Send email to SC | AA10: =IF(E10<=(TODAY()+F10),"Send notification to supplier","No actions") -> Send notification to supplier | AB10: =IF((E10-D10)>720,V10>0, "No actions") -> No actions
A11: 10020995 | B11: =VLOOKUP(A11,'All vendors'!A:Z,2,0) -> Global Safe Salud S.A.S | C11: Serv Agreem | D11: 44986 | E11: 45351 | F11: 5 | G11: =VLOOKUP(A11,'All vendors'!B:E,4,0) -> #N/A | H11: =VLOOKUP(A11,'All vendors'!B:E,3,0) -> #N/A | I11: COL-Cúcuta | J11: =VLOOKUP(A11,'All vendors'!A:Z,13,0) -> 45329.448 | K11: SsC-2500//2023/024 | L11: Ambulance service | M11: =VLOOKUP(A11,'All vendors'!A:Z,11,0) -> Rafael Stiven Parada Dominguez | N11: =VLOOKUP(A11,'All vendors'!A:Z,12,0) -> 0 | O11: =VLOOKUP(A11,'All vendors'!A:Z,15,0) -> contratacion.globalsalud@gmail.com | P11: Lucy del Socorro Peinado | Q11: Banco de Bogotá | R11: GLOBAL SAFE SALUD SAS | S11: Dayana: se tramitará carta de culminación anticipada ya que este servicio de ambulancia no fue utilizado. Fecha finalización 29-02-2024 Y/O HASTA EL AGOTAMIENTO DE LOS RECURSOS Costo de los servicios: HASTA LA SUMA DE $4.000.000. | T11: 0 | U11: 200000 | V11: 0 | Y11: =IF(H11>E11,"No actions","Update ATC") -> #N/A | Z11: =IF(E11<(TODAY()+90),"Send email to SC","No actions") -> Send email to SC | AA11: =IF(E11<=(TODAY()+F11),"Send notification to supplier","No actions") -> Send notification to supplier | AB11: =IF((E11-D11)>720,V11>0, "No actions") -> No actions
A12: 10000402 | B12: =VLOOKUP(A12,'All vendors'!A:Z,2,0) -> Tigers Job Ltda | C12: MSA | D12: 44348 | E12: 45360 | F12: 30 | G12: =VLOOKUP(A12,'All vendors'!B:E,4,0) -> #N/A | H12: =VLOOKUP(A12,'All vendors'!B:E,3,0) -> #N/A | I12: COL-Cúcuta | J12: =VLOOKUP(A12,'All vendors'!A:Z,13,0) -> 45654.532 | K12: MSA/2021/026 | L12: Private Security | M12: =VLOOKUP(A12,'All vendors'!A:Z,11,0) -> Angelica Guerrero Gonzalez | N12: =VLOOKUP(A12,'All vendors'!A:Z,12,0) -> +573152350459 | O12: =VLOOKUP(A12,'All vendors'!A:Z,15,0) -> comercial@tigerjob.com.co | P12: Maria del Carmen Delgado | Q12: Banco de Bogotá | R12: TIGERS JOB Ltda | S12: No se va a renovar. Se realizará un proceso nuevo RFQ para un contrato mayor a 2500 USD, ya que el MSA se agotaron las enmiendas y tiene un Waiver. | T12: 0 | U12: =17774998+17774998+17774998+17774998+17774998+17774998+17774998+17774998+17774998+17774998+10063916+10063916+10063916+10063916+4035567+4035567+4035567+17267416.5+4035567+4035567+3704277+3704277+3704277+3704277 -> 2.70268e+08 | V12: 0 | Y12: =IF(H12>E12,"No actions","Update ATC") -> #N/A | Z12: =IF(E12<(TODAY()+90),"Send email to SC","No actions") -> Send email to SC | AA12: =IF(E12<=(TODAY()+F12),"Send notification to supplier","No actions") -> Send notification to supplier | AB12: =IF((E12-D12)>720,V12>0, "No actions") -> FALSE
A13: 10000430 | B13: =VLOOKUP(A13,'All vendors'!A:Z,2,0) -> Sociedad Taxis Satelital Taxsatel SAS | C13: Serv Agreem | D13: 44278 | E13: 45373 | F13: 30 | G13: =VLOOKUP(A13,'All vendors'!B:E,4,0) -> #N/A | H13: =VLOOKUP(A13,'All vendors'!B:E,3,0) -> #N/A | I13: COL-Cúcuta | J13: =VLOOKUP(A13,'All vendors'!A:Z,13,0) -> 45654.504 | K13: SC+2500/2023/071 | L13: Transp Services | M13: =VLOOKUP(A13,'All vendors'!A:Z,11,0) -> Jose Nicolas Pineda | N13: =VLOOKUP(A13,'All vendors'!A:Z,12,0) -> +573013165339 | O13: =VLOOKUP(A13,'All vendors'!A:Z,15,0) -> nicolaspineda@hotmail.com | P13: Jesus A. Daza | S13: No se renovara. Se firmo y envio carta de finalización anticipada. | T13: 0 | V13: 0 | Y13: =IF(H13>E13,"No actions","Update ATC") -> #N/A | Z13: =IF(E13<(TODAY()+90),"Send email to SC","No actions") -> Send email to SC | AA13: =IF(E13<=(TODAY()+F13),"Send notification to supplier","No actions") -> Send notification to supplier | AB13: =IF((E13-D13)>720,V13>0, "No actions") -> FALSE
A14: 10003150 | B14: =VLOOKUP(A14,'All vendors'!A:Z,2,0) -> Servicios de salud ocupacional Unimsalud S.A.S. | C14: Serv Agreem | D14: 45017 | E14: 45382 | F14: 5 | G14: =VLOOKUP(A14,'All vendors'!B:E,4,0) -> #N/A | H14: =VLOOKUP(A14,'All vendors'!B:E,3,0) -> #N/A | I14: COL-Bogotá | J14: =VLOOKUP(A14,'All vendors'!A:Z,13,0) -> 45419.643 | K14: SC+2500/2023/078 | L14: Health Services | M14: =VLOOKUP(A14,'All vendors'!A:Z,11,0) -> Mariela Rodriguez de Rodriguez | N14: =VLOOKUP(A14,'All vendors'!A:Z,12,0) -> +576012100478 | O14: =VLOOKUP(A14,'All vendors'!A:Z,15,0) -> unimsalud@unimsalud.com.co | P14: Mariela Rodriguez de Rodriguez | Q14: BBVA | R14: Servicios de salud Ocupacional Unimsalud | S14: No se va a renovar. | T14: 0 | V14: 0 | Y14: =IF(H14>E14,"No actions","Update ATC") -> #N/A | Z14: =IF(E14<(TODAY()+90),"Send email to SC","No actions") -> Send email to SC | AA14: =IF(E14<=(TODAY()+F14),"Send notification to supplier","No actions") -> Send notification to supplier | AB14: =IF((E14-D14)>720,V14>0, "No actions") -> No actions
A15: 10000356 | B15: =VLOOKUP(A15,'All vendors'!A:Z,2,0) -> #N/A | C15: MPA | D15: 45323 | E15: 45688 | F15: 30 | G15: =VLOOKUP(A15,'All vendors'!B:E,4,0) -> #N/A | H15: =VLOOKUP(A15,'All vendors'!B:E,3,0) -> #N/A | I15: COL-Bogotá | J15: =VLOOKUP(A15,'All vendors'!A:Z,13,0) -> #N/A | K15: MPA/2023/029 | L15: Equipos Tech | M15: =VLOOKUP(A15,'All vendors'!A:Z,11,0) -> #N/A | N15: =VLOOKUP(A15,'All vendors'!A:Z,12,0) -> #N/A | O15: =VLOOKUP(A15,'All vendors'!A:Z,15,0) -> #N/A | P15: Mercedez Espinoza | S15: Se envio una carta de cancelacion anticipada de contrato ya que no pueden cumplir con los valores pactads en el anexo A | U15: 0 | V15: 0 | W15: =VLOOKUP(A15,'All vendors'!A:Z,17,0) -> #N/A | X15: 0
A16: 10013763 | B16: =VLOOKUP(A16,'All vendors'!A:Z,2,0) -> Empresa Social del Estado Bellosalud | C16: MSA | D16: 44706 | E16: 45436 | F16: 5 | G16: =VLOOKUP(A16,'All vendors'!B:E,4,0) -> #N/A | H16: =VLOOKUP(A16,'All vendors'!B:E,3,0) -> #N/A | I16: COL-Medellín | J16: =VLOOKUP(A16,'All vendors'!A:Z,13,0) -> 45497.237 | K16: MSA/2021/035 | L16: Health Services | M16: =VLOOKUP(A16,'All vendors'!A:Z,11,0) -> Giovanni Alberto Muñoz García | N16: =VLOOKUP(A16,'All vendors'!A:Z,12,0) -> +573232885428 | O16: =VLOOKUP(A16,'All vendors'!A:Z,15,0) -> cuentasmedicasbellosalud@gmail.com | P16: Alfonso Montoya | Q16: Banco de Bogotá | R16: E.S.E. Bello Salud | S16: Sin Observaciones | U16: 29864254 | V16: 0 | W16: =VLOOKUP(A16,'All vendors'!A:Z,17,0) -> 999999999 | X16: 0 | AA16: =IF(H16>E16,"No actions","Update ATC") -> #N/A | AB16: =IF(E16<(TODAY()+90),"Send email to SC","No actions") -> Send email to SC | AC16: =IF(E16<=(TODAY()+F16),"Send notification to supplier","No actions") -> Send notification to supplier | AD16: =IF((E16-D16)>720,X16>0, "No actions") -> FALSE
A17: 10050019 | B17: =VLOOKUP(A17,'All vendors'!A:Z,2,0) -> Oro Company SAS | C17: Serv Agreem | D17: 45359 | E17: 45442 | F17: 30 | G17: =VLOOKUP(A17,'All vendors'!B:E,4,0) -> #N/A | H17: =VLOOKUP(A17,'All vendors'!B:E,3,0) -> #N/A | I17: COL-Bogotá | J17: No tiene ATC | K17: SsC-2500-2024-049 | L17: Ilustration | M17: =VLOOKUP(A17,'All vendors'!A:Z,11,0) -> PEREA PALACIOS MARTHA | N17: =VLOOKUP(A17,'All vendors'!A:Z,12,0) -> +573132184740 | O17: =VLOOKUP(A17,'All vendors'!A:Z,15,0) -> administracion@orotaller.com | P17: Claudia Patricia Flórez | Q17: Davivienda | R17: Movlife SAS | S17: Sin Observaciones | U17: 7735000 | V17: 0 | W17: =VLOOKUP(A17,'All vendors'!A:Z,17,0) -> 2400 | X17: 0
A18: 10000403 | B18: =VLOOKUP(A18,'All vendors'!A:Z,2,0) -> Asociacion Profamilia | C18: MSA | D18: 44355 | E18: 45443 | F18: 30 | G18: =VLOOKUP(A18,'All vendors'!B:E,4,0) -> #N/A | H18: =VLOOKUP(A18,'All vendors'!B:E,3,0) -> #N/A | I18: COL-Bogotá | J18: =VLOOKUP(A18,'All vendors'!A:Z,13,0) -> 45804.216 | K18: MSA/2020/020 | L18: Health Services | M18: =VLOOKUP(A18,'All vendors'!A:Z,11,0) -> Juliana Marín Restrepo | N18: =VLOOKUP(A18,'All vendors'!A:Z,12,0) -> +573124116546 | O18: =VLOOKUP(A18,'All vendors'!A:Z,15,0) -> juliana.marin@profamilia.com | P18: Jorge Ivàn Rojo | Q18: Banco de Bogotá | R18: ASOCIACION PROFAMILIA | S18: Sin Observaciones | U18: 2200929443 | V18: 0 | W18: =VLOOKUP(A18,'All vendors'!A:Z,17,0) -> 999999999 | X18: 1 | AA18: =IF(H18>E18,"No actions","Update ATC") -> #N/A | AB18: =IF(E18<(TODAY()+90),"Send email to SC","No actions") -> Send email to SC | AC18: =IF(E18<=(TODAY()+F18),"Send notification to supplier","No actions") -> Send notification to supplier | AD18: =IF((E18-D18)>720,X18>0, "No actions") -> TRUE
A19: 10050020 | B19: =VLOOKUP(A19,'All vendors'!A:Z,2,0) -> Laura Natalia Noriega Gomez | C19: Serv Agreem | D19: 18-Marz-24 | E19: 45443 | F19: 30 | G19: =VLOOKUP(A19,'All vendors'!B:E,4,0) -> #N/A | H19: =VLOOKUP(A19,'All vendors'!B:E,3,0) -> #N/A | I19: COL-Bogotá | J19: No tiene ATC | K19: SC-2500/2024/048 | L19: Graphic Design | M19: =VLOOKUP(A19,'All vendors'!A:Z,11,0) -> Laura Natalia Noriega Gomez | N19: =VLOOKUP(A19,'All vendors'!A:Z,12,0) -> +573168203747 | O19: =VLOOKUP(A19,'All vendors'!A:Z,15,0) -> noriegagomezln@gmail.com | P19: Franklin Cardenas | Q19: Bank of America | S19: Tope: 9.500.000 COP | T19: =9500000/4000 -> 2375 | U19: 9500000 | V19: 0 | W19: =VLOOKUP(A19,'All vendors'!A:Z,17,0) -> 19000 | X19: 0
A20: 10000528 | B20: =VLOOKUP(A20,'All vendors'!A:Z,2,0) -> T&T Col S.A.S | C20: MSA | D20: 44409 | E20: 45504 | F20: 30 | G20: =VLOOKUP(A20,'All vendors'!B:E,4,0) -> #N/A | H20: =VLOOKUP(A20,'All vendors'!B:E,3,0) -> #N/A | I20: COL-Cúcuta | J20: =VLOOKUP(A20,'All vendors'!A:Z,13,0) -> 45654.504 | K20: MSA/2021/027 | L20: Transportation | M20: =VLOOKUP(A20,'All vendors'!A:Z,11,0) -> María Fernanda Tarazona Rojas | N20: =VLOOKUP(A20,'All vendors'!A:Z,12,0) -> +573126852001 | O20: =VLOOKUP(A20,'All vendors'!A:Z,15,0) -> tytcol.operaciones@gmail.com | P20: Eglen Kevin Castillo | Q20: BBVA | R20: T&T COL SAS | S20: El contrato terminará, se comienza nuevo proceso de RFQ | T20: 0 | U20: 511895000 | V20: 0 | W20: =VLOOKUP(A20,'All vendors'!A:Z,17,0) -> 999999999 | X20: 1 | AA20: =IF(H20>E20,"No actions","Update ATC") -> #N/A | AB20: =IF(E20<(TODAY()+90),"Send email to SC","No actions") -> Send email to SC | AC20: =IF(E20<=(TODAY()+F20),"Send notification to supplier","No actions") -> Send notification to supplier | AD20: =IF((E20-D20)>720,X20>0, "No actions") -> TRUE

Sheet Spend by Vendor
A1: Vendor Party # | B1: Entity | C1: Vendor Account # | D1: Vendor Name | E1: Vendor Group | F1: ATC Check ID | G1: Integra ATC Sub Date | H1: ATC Clearance Exp Date | I1: IRC ATC Status | J1: Vendor Hold Status | K1: Anticipated Spend | L1: Total Spending | M1: Overspent | N1: Vendor Created Date | O1: Vendor Modified Date
A2: 000000017 | B2: 4COL | C2: 10020295 | D2: Laura Yu | E2: EMP | F2: 82544 | I2: Cleared | J2: All | K2: 0 | L2: 0 | M2: N | N2: 44880 | O2: 44880
A3: 000000178 | B3: 4COL | C3: 10000451 | D3: Asociación Civil amigos del Hospital de Niños de Valencia | E3: SUB | I3: Cleared | J3: No | K3: 0 | L3: 0 | M3: N | N3: 44603 | O3: 44701
A4: 000000345 | B4: 4COL | C4: 10000454 | D4: Madres y Padres Por Los Niños En Venezuela (MAPANI VZLA) | E4: SUB | F4: 146434 | G4: 2/26/2021 | H4: 2/10/2023 | I4: Expired | J4: All Except Payment | K4: 0 | L4: 0 | M4: N | N4: 44603 | O4: 44968
A5: 000000499 | B5: 4COL | C5: 10004362 | D5: Asociación Larense de Planificación Familiar | E5: SUB | F5: 254426 | G5: 4/28/2023 | H5: 4/29/2024 | I5: Cleared | J5: No | K5: 0 | L5: 0 | M5: N | N5: 44697 | O5: 45048
A6: 000001065 | B6: 4COL | C6: 10012617 | D6: Olivia Hadley | E6: EMP | J6: All | K6: 0 | L6: 0 | M6: N | N6: 44784 | O6: 44784
A7: 000001331 | B7: 4COL | C7: 10000003 | D7: Rosalind Montanez | E7: EMP | J7: No | K7: 0 | L7: 0 | M7: N | N7: 44497 | O7: 44497
A8: 000001690 | B8: 4COL | C8: 10009561 | D8: Elena Wallraff | E8: EMP | J8: No | K8: 0 | L8: 0 | M8: N | N8: 44750 | O8: 44750
A9: 000001770 | B9: 4COL | C9: 10013463 | D9: To be determined (TBD) | E9: SUB | J9: All | K9: 0 | L9: 0 | M9: N | N9: 44796 | O9: 44796
A10: 000001977 | B10: 4COL | C10: 10009484 | D10: Yolanda Barbera Barbera | E10: CONT | J10: No | K10: 0 | L10: 37874.86 | M10: Y | N10: 44749 | O10: 44944
A11: 000002165 | B11: 4COL | C11: 10032300 | D11: Martine Dherte | E11: EMP | J11: No | K11: 0 | L11: 0 | M11: N | N11: 45062 | O11: 45062
A12: 000002304 | B12: 4COL | C12: 10002402 | D12: Mohammed Mahdi | E12: EMP | J12: No | K12: 0 | L12: 0 | M12: N | N12: 44683 | O12: 44944
A13: 000002676 | B13: 4COL | C13: 10025082 | D13: Juliet Stein | E13: CONT | J13: All | K13: 0 | L13: 0 | M13: N | N13: 44946 | O13: 44946
A14: 000003448 | B14: 4COL | C14: 10030596 | D14: Helen Rolston-Clemmer | E14: EMP | J14: All | K14: 0 | L14: 0 | M14: N | N14: 45037 | O14: 45037
A15: 000003638 | B15: 4COL | C15: 10002838 | D15: Heather Molloy | E15: EMP | J15: No | K15: 0 | L15: 0 | M15: N | N15: 44686 | O15: 44686
A16: 000004658 | B16: 4COL | C16: 10007031 | D16: Maria Nattaly Dulcey Chaparro | E16: CONT | J16: No | K16: 0 | L16: 0 | M16: N | N16: 44725 | O16: 44725
A17: 000004709 | B17: 4COL | C17: 10006317 | D17: Paola Andrea Buendia Torres | E17: TRADE | F17: 207018 | G17: 6/6/2022 | H17: 6/7/2023 | I17: Cleared | J17: No | K17: 2400 | L17: 0 | M17: N | N17: 44718 | O17: 44721
A18: 000005421 | B18: 4COL | C18: 10000456 | D18: Planson International Corporation | E18: TRADE | F18: 246792 | G18: 2/27/2023 | H18: 2/26/2024 | I18: Cleared | J18: No | K18: 1000000 | L18: 518466.71 | M18: N | N18: 44603 | O18: 44984
A19: 000005461 | B19: 4COL | C19: 10000457 | D19: Taylor Made Graphics Co. Inc. | E19: TRADE | F19: 246311 | G19: 2/23/2023 | H19: 2/22/2024 | I19: Cleared | J19: No | K19: 500000 | L19: 24914.45 | M19: N | N19: 44603 | O19: 44988
A20: 000006750 | B20: 4COL | C20: 10016591 | D20: Laura Rossello | E20: CONT | J20: No | K20: 0 | L20: 7000 | M20: Y | N20: 44827 | O20: 44937
A21: 000006872 | B21: 4COL | C21: 10004041 | D21: Kate Say | E21: EMP | J21: All | K21: 0 | L21: 0 | M21: N | N21: 44693 | O21: 44693
A22: 000006959 | B22: 4COL | C22: 10008219 | D22: Esperance Nshimiyimana | E22: EMP | J22: All | K22: 0 | L22: 0 | M22: N | N22: 44736 | O22: 44736
A23: 000006960 | B23: 4COL | C23: 10000744 | D23: Norman Slawsky | E23: INTVOL | J23: No | K23: 0 | L23: 0 | M23: N | N23: 44664 | O23: 44664
A24: 000007068 | B24: 4COL | C24: 10013103 | D24: Alphonse Kitoga | E24: CONT | J24: No | K24: 0 | L24: 0 | M24: N | N24: 44791 | O24: 45022
A25: 000007488 | B25: 4COL | C25: 10021562 | D25: Gordana Ivkovic-Grujic | E25: EMP | J25: No | K25: 0 | L25: 0 | M25: N | N25: 44896 | O25: 44896
A26: 000008203 | B26: 4COL | C26: 10030338 | D26: Alphonse Soungalo Diakite | E26: EMP | J26: All | K26: 0 | L26: 0 | M26: N | N26: 45034 | O26: 45034
A27: 000008350 | B27: 4COL | C27: 10013375 | D27: Shama Imtiaz | E27: EMP | J27: No | K27: 0 | L27: 0 | M27: N | N27: 44795 | O27: 44795
A28: 000008473 | B28: 4COL | C28: 10028778 | D28: Abdikadir Hassan | E28: EMP | J28: All | K28: 0 | L28: 0 | M28: N | N28: 45001 | O28: 45001
A29: 000008614 | B29: 4COL | C29: 10020847 | D29: Damien Bigirimana | E29: EMP | J29: All | K29: 0 | L29: 0 | M29: N | N29: 44886 | O29: 44886
A30: 000008673 | B30: 4COL | C30: 10018969 | D30: Mireine Bulonza | E30: EMP | J30: No | K30: 0 | L30: 0 | M30: N | N30: 44860 | O30: 44860
A31: 000009227 | B31: 4COL | C31: 10006333 | D31: Vannina Kaneza | E31: EMP | J31: No | K31: 0 | L31: 0 | M31: N | N31: 44718 | O31: 44944
... A94: 000018955 | B94: 4COL | C94: 10029326 | D94: Acacia Keith | E94: EMP | J94: All | K94: 0 | L94: 0 | M94: N | N94: 45012 | O94: 45012
A95: 000019464 | B95: 4COL | C95: 10003669 | D95: Asociación Civil Acción Zuliana por la Vida | E95: SUB | F95: 254430 | G95: 4/28/2023 | H95: 4/29/2024 | I95: Cleared | J95: No | K95: 2501 | L95: 0 | M95: N | N95: 44692 | O95: 45049
A96: 000019602 | B96: 4COL | C96: 10026473 | D96: QUAMED | E96: TRADE | F96: 244518 | G96: 2/10/2023 | H96: 2/9/2024 | I96: Cleared | J96: No | K96: 50000 | L96: 38713.91 | M96: N | N96: 44967 | O96: 44967
A97: 000020446 | B97: 4COL | C97: 10006868 | D97: Graciela Pasquier | E97: EMP | J97: No | K97: 0 | L97: 2000 | M97: Y | N97: 44722 | O97: 44722
A98: 000020466 | B98: 4COL | C98: 10000017 | D98: Maria Menjivar | E98: EMP | J98: No | K98: 0 | L98: 1406.53 | M98: Y | N98: 44497 | O98: 44497
